2025-06-23 16:50:56,461 INFO: attempt 1 failed for https://opencitations.net/index/api/v2/references/doi:10.5281%2Fzenodo.12679614: ('Connection aborted.', RemoteDisconnected('Remote end closed connection without response'))
2025-06-23 17:52:42,773 INFO: attempt 1 failed for https://opencitations.net/index/api/v2/citations/doi:10.5281%2Fzenodo.3956457: HTTPSConnectionPool(host='opencitations.net', port=443): Read timed out. (read timeout=15)
2025-06-23 17:52:53,142 INFO: attempt 2 failed for https://opencitations.net/index/api/v2/citations/doi:10.5281%2Fzenodo.3956457: HTTPSConnectionPool(host='opencitations.net', port=443): Max retries exceeded with url: /index/api/v2/citations/doi:10.5281%2Fzenodo.3956457 (Caused by SSLError(SSLCertVerificationError(1, '[SSL: CERTIFICATE_VERIFY_FAILED] certificate verify failed: self-signed certificate (_ssl.c:1028)')))
2025-06-23 17:53:03,259 INFO: attempt 3 failed for https://opencitations.net/index/api/v2/citations/doi:10.5281%2Fzenodo.3956457: HTTPSConnectionPool(host='opencitations.net', port=443): Max retries exceeded with url: /index/api/v2/citations/doi:10.5281%2Fzenodo.3956457 (Caused by SSLError(SSLCertVerificationError(1, '[SSL: CERTIFICATE_VERIFY_FAILED] certificate verify failed: self-signed certificate (_ssl.c:1028)')))
2025-06-23 17:53:13,638 INFO: attempt 4 failed for https://opencitations.net/index/api/v2/citations/doi:10.5281%2Fzenodo.3956457: HTTPSConnectionPool(host='opencitations.net', port=443): Max retries exceeded with url: /index/api/v2/citations/doi:10.5281%2Fzenodo.3956457 (Caused by SSLError(SSLCertVerificationError(1, '[SSL: CERTIFICATE_VERIFY_FAILED] certificate verify failed: self-signed certificate (_ssl.c:1028)')))
2025-06-23 17:53:23,640 ERROR: 10.5281/zenodo.3956457 – giving up: \u274c all retries failed for https://opencitations.net/index/api/v2/citations/doi:10.5281%2Fzenodo.3956457
2025-06-23 17:53:24,752 INFO: attempt 1 failed for https://opencitations.net/index/api/v2/references/doi:10.5281%2Fzenodo.11059821: HTTPSConnectionPool(host='opencitations.net', port=443): Max retries exceeded with url: /index/api/v2/references/doi:10.5281%2Fzenodo.11059821 (Caused by SSLError(SSLCertVerificationError(1, '[SSL: CERTIFICATE_VERIFY_FAILED] certificate verify failed: self-signed certificate (_ssl.c:1028)')))
2025-06-23 17:53:35,127 INFO: attempt 2 failed for https://opencitations.net/index/api/v2/references/doi:10.5281%2Fzenodo.11059821: HTTPSConnectionPool(host='opencitations.net', port=443): Max retries exceeded with url: /index/api/v2/references/doi:10.5281%2Fzenodo.11059821 (Caused by SSLError(SSLCertVerificationError(1, '[SSL: CERTIFICATE_VERIFY_FAILED] certificate verify failed: self-signed certificate (_ssl.c:1028)')))
2025-06-23 17:54:00,570 INFO: attempt 3 failed for https://opencitations.net/index/api/v2/references/doi:10.5281%2Fzenodo.11059821: HTTPSConnectionPool(host='opencitations.net', port=443): Read timed out. (read timeout=15)
2025-06-23 18:04:38,591 INFO: attempt 1 failed for https://opencitations.net/index/api/v2/references/doi:10.5281%2Fzenodo.5030913: ('Connection aborted.', RemoteDisconnected('Remote end closed connection without response'))
2025-06-23 18:20:56,726 INFO: attempt 1 failed for https://opencitations.net/index/api/v2/citations/doi:10.5281%2Fzenodo.7669736: HTTPSConnectionPool(host='opencitations.net', port=443): Read timed out. (read timeout=15)
2025-06-23 18:21:06,859 INFO: attempt 2 failed for https://opencitations.net/index/api/v2/citations/doi:10.5281%2Fzenodo.7669736: HTTPSConnectionPool(host='opencitations.net', port=443): Max retries exceeded with url: /index/api/v2/citations/doi:10.5281%2Fzenodo.7669736 (Caused by SSLError(SSLCertVerificationError(1, '[SSL: CERTIFICATE_VERIFY_FAILED] certificate verify failed: self-signed certificate (_ssl.c:1028)')))
2025-06-23 18:21:17,025 INFO: attempt 3 failed for https://opencitations.net/index/api/v2/citations/doi:10.5281%2Fzenodo.7669736: HTTPSConnectionPool(host='opencitations.net', port=443): Max retries exceeded with url: /index/api/v2/citations/doi:10.5281%2Fzenodo.7669736 (Caused by SSLError(SSLCertVerificationError(1, '[SSL: CERTIFICATE_VERIFY_FAILED] certificate verify failed: self-signed certificate (_ssl.c:1028)')))
2025-06-23 18:21:28,886 INFO: attempt 4 failed for https://opencitations.net/index/api/v2/citations/doi:10.5281%2Fzenodo.7669736: HTTPSConnectionPool(host='opencitations.net', port=443): Max retries exceeded with url: /index/api/v2/citations/doi:10.5281%2Fzenodo.7669736 (Caused by SSLError(SSLCertVerificationError(1, '[SSL: CERTIFICATE_VERIFY_FAILED] certificate verify failed: self-signed certificate (_ssl.c:1028)')))
2025-06-23 18:21:38,887 ERROR: 10.5281/zenodo.7669736 – giving up: \u274c all retries failed for https://opencitations.net/index/api/v2/citations/doi:10.5281%2Fzenodo.7669736
2025-06-23 18:21:41,331 INFO: attempt 1 failed for https://opencitations.net/index/api/v2/references/doi:10.5281%2Fzenodo.3884109: HTTPSConnectionPool(host='opencitations.net', port=443): Max retries exceeded with url: /index/api/v2/references/doi:10.5281%2Fzenodo.3884109 (Caused by SSLError(SSLCertVerificationError(1, '[SSL: CERTIFICATE_VERIFY_FAILED] certificate verify failed: self-signed certificate (_ssl.c:1028)')))
2025-06-23 18:21:51,829 INFO: attempt 2 failed for https://opencitations.net/index/api/v2/references/doi:10.5281%2Fzenodo.3884109: HTTPSConnectionPool(host='opencitations.net', port=443): Max retries exceeded with url: /index/api/v2/references/doi:10.5281%2Fzenodo.3884109 (Caused by SSLError(SSLCertVerificationError(1, '[SSL: CERTIFICATE_VERIFY_FAILED] certificate verify failed: self-signed certificate (_ssl.c:1028)')))
2025-06-23 18:22:18,591 INFO: attempt 1 failed for https://opencitations.net/index/api/v2/citations/doi:10.5281%2Fzenodo.3884109: HTTPSConnectionPool(host='opencitations.net', port=443): Read timed out. (read timeout=15)
2025-06-23 19:30:35,482 INFO: attempt 1 failed for https://opencitations.net/index/api/v2/references/doi:10.5281%2Fzenodo.5076594: ('Connection aborted.', ConnectionResetError(10054, "Connessione in corso interrotta forzatamente dall'host remoto", None, 10054, None))
2025-06-23 19:58:52,017 INFO: attempt 1 failed for https://opencitations.net/index/api/v2/citations/doi:10.5281%2Fzenodo.14909591: ('Connection aborted.', ConnectionResetError(10054, "Connessione in corso interrotta forzatamente dall'host remoto", None, 10054, None))
2025-06-23 20:26:12,439 INFO: attempt 1 failed for https://opencitations.net/index/api/v2/references/doi:10.5281%2Fzenodo.8285609: HTTPSConnectionPool(host='opencitations.net', port=443): Read timed out. (read timeout=15)
2025-06-23 20:45:16,178 INFO: attempt 1 failed for https://opencitations.net/index/api/v2/citations/doi:10.5281%2Fzenodo.7590574: 400 Client Error: Bad Request for url: https://opencitations.net/index/api/v2/citations/doi:10.5281%2Fzenodo.7590574
2025-06-24 12:02:11,585 INFO: attempt 1 failed for https://opencitations.net/index/api/v2/citations/doi:10.5281%2Fzenodo.4480106: HTTPSConnectionPool(host='opencitations.net', port=443): Read timed out. (read timeout=15)
2025-06-24 14:45:21,881 INFO: attempt 1 failed for https://opencitations.net/index/api/v2/references/doi:10.5281%2Fzenodo.7041697: HTTPSConnectionPool(host='opencitations.net', port=443): Read timed out. (read timeout=15)
2025-06-24 14:45:43,913 INFO: attempt 2 failed for https://opencitations.net/index/api/v2/references/doi:10.5281%2Fzenodo.7041697: HTTPSConnectionPool(host='opencitations.net', port=443): Read timed out. (read timeout=15)
2025-06-24 14:46:05,942 INFO: attempt 3 failed for https://opencitations.net/index/api/v2/references/doi:10.5281%2Fzenodo.7041697: HTTPSConnectionPool(host='opencitations.net', port=443): Read timed out. (read timeout=15)
2025-06-24 14:46:12,944 ERROR: 10.5281/zenodo.7041697 – giving up: \u274c all retries failed for https://opencitations.net/index/api/v2/references/doi:10.5281%2Fzenodo.7041697
2025-06-24 14:49:46,834 INFO: attempt 1 failed for https://opencitations.net/index/api/v2/references/doi:10.5281%2Fzenodo.7488357: HTTPSConnectionPool(host='opencitations.net', port=443): Read timed out. (read timeout=15)
2025-06-24 15:19:11,488 INFO: attempt 1 failed for https://opencitations.net/index/api/v2/references/doi:10.5281%2Fzenodo.5069838: HTTPSConnectionPool(host='opencitations.net', port=443): Read timed out. (read timeout=15)
